Workbook

Sheet How to Use
A1: LookOut — Alpha Testing Results (template)
A2: Filled by the alpha_eval tool. Yellow = input, grey = formula. Never edit formulas.
A4: HOW IT WORKS
A5: 1 | B5: Before detection, the answer key is typed for each clip: every violation (type, start time, Violation / Look-alike / No violation).
A6: 2 | B6: Detection runs on the WHOLE clip with LookOut's own logic. It never sees the answer key.
A7: 3 | B7: After detection, the tool matches alerts to answer-key rows. Alerts that match nothing become 'Unmatched alert' rows and a reviewer tags them.
A8: 4 | B8: Scores appear automatically. 'Check' compares the tool's score with this sheet's formulas — every MISMATCH must be fixed before reporting.
A10: WHAT TP / TN / FP / FN MEAN
A11: TP | B11: True Positive: the test said "yes" and the actual reality was "yes." (Violation happened → system alerted in time.)
A12: TN | B12: True Negative: the test said "no" and the actual reality was "no." (Look-alike / no violation → system stayed quiet.)
A13: FP | B13: False Positive: the test said "yes" but the actual reality was "no." (False alarm.)
A14: FN | B14: False Negative: the test said "no" but the actual reality was "yes." (Violation missed, too late, or alerted as the wrong type.)
A16: SCORING RULES
A17: • | B17: Only alerts that reached Possible or Likely count (Monitoring only if Settings says Yes). Alert time = when it first reached a counting status.
A18: • | B18: Matching: each answer-key row takes at most one alert of its type; each alert fills at most one row; rows are filled in start-time order.
A19: • | B19: An alert can match from (start − start tolerance) up to the deadline. Deadline = start + waiting time + alert window (60 s).
A20: • | B20: Waiting time: parking = parking threshold; drinking = inuman group duration; others 0. Main set uses shortened values, Validation set uses real ones.
A21: • | B21: Violation row: matched in time → TP, otherwise FN. Look-alike / No-violation row: an alert of that type matched → FP, otherwise TN.
A22: • | B22: TN only exists for types deliberately tested as look-alike / no violation — never for types that simply didn't appear.
A23: • | B23: Unmatched alert tags: Duplicate (same act alerted again, no FP) · False alarm (actors, FP) · Unscripted – false alarm (bystander, FP) · Unscripted – real violation (excluded, reported separately) · Late (real act alerted after the deadline, no extra FP; the act is already an FN).
A24: • | B24: Action start: parking = vehicle enters the zone; holdup = rapid approach / knife reveal; inuman = group formed and drinking; smoking/drinking = first light/puff/sip.
A26: EXAMPLE (3-min smoking clip)
B27: Answer key: Smoking 0:30 (Actor 1), Smoking 1:30 (Actor 2). Alerts: Smoking 0:41, Smoking 1:38, Drinking 1:46 on a passing group.
A28: → | B28: Row 1 → TP (delay 11 s). Row 2 → TP (delay 8 s). Drinking 1:46 → Unmatched alert, tagged 'Unscripted – false alarm' → Drinking FP.
A30: SHEETS FOR THE PAPER
A31: • | B31: Summary (main results) · Validation (real thresholds) · Breakdown (distance, time of day, alert level, AI checker, delay, unmatched tags, speed) · Confusion Matrix.
A33: CELL COLOURS
B34: Yellow = input. Grey = formula. Outcome: green TP/TN, red FP, orange FN, yellow Needs tag / Needs start, grey Duplicate, blue Excluded. Red MISMATCH = tool and sheet disagree.

Sheet Settings
A1: Test Settings
A2: Filled by the alpha_eval tool (yellow). Scoring formulas read these values. Keep them fixed for the whole test.
A4: Setting | B4: Value | C4: Note
A5: Alert window (seconds) | B5: 60 | C5: Alert must reach a counting status within this many seconds after the act starts (plus any waiting time).
A6: Start tolerance (seconds) | B6: 5 | C6: An alert up to this many seconds BEFORE the typed start can still match (start times are typed by hand).
A7: Count 'Monitoring' as an alert? | B7: No | C7: No = only Possible / Likely count.
A8: Parking threshold — Main set (s) | B8: 20 | C8: Shortened parking threshold used for Main-set clips.
A9: Parking threshold — Validation set (s) | B9: 300 | C9: Real Ord. No. 601 threshold (5 min), used for Validation-set clips.
A10: Drinking group duration — Main set (s) | B10: 60 | C10: Shortened inuman duration used for Main-set clips.
A11: Drinking group duration — Validation set (s) | B11: 600 | C11: Real deployment duration, used for Validation-set clips.
A12: Model version | B12: merged_v2.pt | C12: Detection model file.
A13: Model SHA-256 | B13: 8e9c77665b243ce8aebe9457ca2bc4f9fd11f09d0d88e406789d42172d2e8bbb | C13: Filled by the tool.
A14: Scoring spec | B14: v6.1 | C14: Monitoring / Possible / Likely scoring version.
A15: Smoking dwell (s) | B15: 3 | C15: From LookOut SystemSettings snapshot.
A16: Other detection settings | B16: {"parking_enabled":true,"parking_confidence":35,"parking_dwell":60,"parking_move_tolerance":40,"smoking_enabled":true,"smoking_confidence":30,"thief_enabled":true,"thief_confidence":30,"thief_dwell":3,"drinking_enabled":true,"drinking_confidence":35,"drinking_dwell":8,"drinking_hours_enabled":false,"drinking_start":"16:00:00","drinking_end":"00:00:00","drinking_min_group":2,"drinking_group_duration":60,"drinking_held_dwell":24,"drinking_evidence_max_age":12,"drinking_mouth_proximity":3.0,"drinking_cooldown_center_dist":1.5,"vlm_enabled":true,"vlm_endpoint":"http://localhost:11434","vlm_model":"qwen3-vl:2b-instruct","vlm_timeout":120,"vlm_frames":8,"vlm_max_edge":640,"vlm_async":true,"object_confirm_seconds":2.0,"cue_hold_seconds":5.0,"monitoring_min_seconds":3.0,"smoking_puff_count":3,"smoking_puff_window_minutes":5.0,"holdup_loiter_seconds":20,"holdup_near_person_heights":1.75,"vlm_model_holdup":"qwen3-vl:4b-instruct","show_testing_tools":true,"auto_start_detection":false,"alert_cooldown":120,"evidence_retention_days":30,"evidence_auto_purge":false} | C16: Short JSON of the remaining SystemSettings values used.
A17: Camera | B17: Hikvision DS-2CD1047G2-LUF | C17: Installed position, full resolution.
A18: LookOut git commit | B18: e6af55083d67970ee75f85799553583f15b9fd8f (+dirty) | C18: Commit hash of lookout_backend (+dirty if uncommitted changes).
A19: alpha_eval tool version | B19: 1.0.0 | C19: Filled by the tool.
A20: Export date | B20: 2026-10-18 00:24 | C20: Filled by the tool.
A21: Results basis | B21: NOT FINAL (settings not consistent; 1 row(s) need a tag/start) — All finished clips (reviewed or not), latest run per clip | C21: e.g. 'Reviewed clips only, latest run per clip'.
A22: Settings consistency | B22: MIXED — overrides_in_memory.parking_threshold_sec, parking_threshold_main_sec (re-run PRK-V01), parking_threshold_main_sec (re-run SMK-V01) | C22: 'CONSISTENT' or 'MIXED — <what differs>'. Don't report MIXED results.

Sheet Clips
A1: Clips — one row per video
A2: Planned clips are pre-listed. The tool updates status columns and adds new clips in spare rows. The answer key lives in Results Log.
A4: Clip ID | B4: Planned focus | C4: Scenario | D4: Distance | E4: Time of day | F4: Min. length | G4: Set | H4: Recording status | I4: Video filename | J4: Date recorded | K4: Duration (s) | L4: Run status | M4: Reviewed | N4: Answer-key rows | O4: Total alerts | P4: Processing FPS | Q4: Processing time (s) | R4: Run ID | S4: Notes
A5: SMK-V01 | B5: Smoking | C5: Standing, smoking, facing the camera | D5: Near | E5: Day | F5: 1–2 min | G5: Main | H5: Recorded | I5: test_smoking_trim2.mp4 | J5: 2026-08-18 | K5: 51.55 | L5: Done | M5: Yes | N5: =IF(A5="","",COUNTIFS('Results Log'!$A$5:$A$404,A5,'Results Log'!$B$5:$B$404,"Expected")) | O5: 1 | P5: 1.46 | Q5: 353.5 | R5: 20261017-235836-0b0358
A6: SMK-V02 | B6: Smoking | C6: Standing, smoking, side view | D6: Near | E6: Day | F6: 1–2 min | G6: Main | H6: Not recorded | L6: Not run | M6: No | N6: =IF(A6="","",COUNTIFS('Results Log'!$A$5:$A$404,A6,'Results Log'!$B$5:$B$404,"Expected"))
A7: SMK-V03 | B7: Smoking | C7: Walking slowly while smoking | D7: Near | E7: Day | F7: 1–2 min | G7: Main | H7: Not recorded | L7: Not run | M7: No | N7: =IF(A7="","",COUNTIFS('Results Log'!$A$5:$A$404,A7,'Results Log'!$B$5:$B$404,"Expected"))
A8: SMK-V04 | B8: Smoking | C8: Seated on bench or curb, smoking | D8: Near | E8: Afternoon | F8: 1–2 min | G8: Main | H8: Not recorded | L8: Not run | M8: No | N8: =IF(A8="","",COUNTIFS('Results Log'!$A$5:$A$404,A8,'Results Log'!$B$5:$B$404,"Expected"))
A9: SMK-V05 | B9: Smoking | C9: Standing, smoking across the road | D9: Far | E9: Day | F9: 1–2 min | G9: Main | H9: Not recorded | L9: Not run | M9: No | N9: =IF(A9="","",COUNTIFS('Results Log'!$A$5:$A$404,A9,'Results Log'!$B$5:$B$404,"Expected"))
A10: SMK-V06 | B10: Smoking | C10: Two people smoking together | D10: Near | E10: Afternoon | F10: 1–2 min | G10: Main | H10: Not recorded | L10: Not run | M10: No | N10: =IF(A10="","",COUNTIFS('Results Log'!$A$5:$A$404,A10,'Results Log'!$B$5:$B$404,"Expected"))
A11: SMK-V07 | B11: Smoking | C11: Smoking while partly turned away from camera | D11: Mid | E11: Day | F11: 1–2 min | G11: Main | H11: Not recorded | L11: Not run | M11: No | N11: =IF(A11="","",COUNTIFS('Results Log'!$A$5:$A$404,A11,'Results Log'!$B$5:$B$404,"Expected"))
A12: SMK-V08 | B12: Smoking | C12: Standing, smoking | D12: Near | E12: Night | F12: 1–2 min | G12: Main | H12: Not recorded | L12: Not run | M12: No | N12: =IF(A12="","",COUNTIFS('Results Log'!$A$5:$A$404,A12,'Results Log'!$B$5:$B$404,"Expected"))
A13: SMK-V09 | B13: Smoking | C13: Standing, smoking across the road | D13: Far | E13: Night | F13: 1–2 min | G13: Main | H13: Not recorded | L13: Not run | M13: No | N13: =IF(A13="","",COUNTIFS('Results Log'!$A$5:$A$404,A13,'Results Log'!$B$5:$B$404,"Expected"))
A14: SMK-V10 | B14: Smoking | C14: Smoking while holding a phone in the other hand | D14: Mid | E14: Afternoon | F14: 1–2 min | G14: Main | H14: Not recorded | L14: Not run | M14: No | N14: =IF(A14="","",COUNTIFS('Results Log'!$A$5:$A$404,A14,'Results Log'!$B$5:$B$404,"Expected"))
A15: SMK-L01 | B15: Smoking | C15: Holding a pen near the mouth | D15: Near | E15: Day | F15: 1–2 min | G15: Main | H15: Not recorded | L15: Not run | M15: No | N15: =IF(A15="","",COUNTIFS('Results Log'!$A$5:$A$404,A15,'Results Log'!$B$5:$B$404,"Expected"))
A16: SMK-L02 | B16: Smoking | C16: Phone call, phone held to the face | D16: Near | E16: Afternoon | F16: 1–2 min | G16: Main | H16: Not recorded | L16: Not run | M16: No | N16: =IF(A16="","",COUNTIFS('Results Log'!$A$5:$A$404,A16,'Results Log'!$B$5:$B$404,"Expected"))
A17: SMK-L03 | B17: Smoking | C17: Eating a stick snack (e.g. fishball / banana cue stick) | D17: Mid | E17: Day | F17: 1–2 min | G17: Main | H17: Not recorded | L17: Not run | M17: No | N17: =IF(A17="","",COUNTIFS('Results Log'!$A$5:$A$404,A17,'Results Log'!$B$5:$B$404,"Expected"))
... A34: DRK-L05 | B34: Drinking | C34: Two people chatting with water bottles, shorter than group duration | D34: Near | E34: Night | F34: 2–3 min | G34: Main | H34: Not recorded | L34: Not run | M34: No | N34: =IF(A34="","",COUNTIFS('Results Log'!$A$5:$A$404,A34,'Results Log'!$B$5:$B$404,"Expected"))
A35: PRK-V01 | B35: Parking Obstruction | C35: Car parked over the road edge | D35: Mid | E35: Day | F35: 6–7 min | G35: Main | H35: Recorded | I35: test_parking.mp4 | J35: 2026-08-14 | K35: 96.33 | L35: Done | M35: No | N35: =IF(A35="","",COUNTIFS('Results Log'!$A$5:$A$404,A35,'Results Log'!$B$5:$B$404,"Expected")) | O35: 1 | P35: 2.19 | Q35: 440.2 | R35: 20261017-234601-13cb6a
A36: PRK-V02 | B36: Parking Obstruction | C36: Motorcycle parked over the road edge | D36: Mid | E36: Day | F36: 6–7 min | G36: Main | H36: Recorded | I36: test_parking2.mp4 | J36: 2026-08-17 | K36: 59.17 | L36: Done | M36: No | N36: =IF(A36="","",COUNTIFS('Results Log'!$A$5:$A$404,A36,'Results Log'!$B$5:$B$404,"Expected")) | O36: 1 | P36: 1.87 | Q36: 316.9 | R36: 20261018-001825-c75439
A37: PRK-V03 | B37: Parking Obstruction | C37: Tricycle parked over the road edge | D37: Mid | E37: Afternoon | F37: 6–7 min | G37: Main | H37: Not recorded | L37: Not run | M37: No | N37: =IF(A37="","",COUNTIFS('Results Log'!$A$5:$A$404,A37,'Results Log'!$B$5:$B$404,"Expected"))
A38: PRK-V04 | B38: Parking Obstruction | C38: Car parked over the road edge | D38: Mid | E38: Night | F38: 6–7 min | G38: Main | H38: Not recorded | L38: Not run | M38: No | N38: =IF(A38="","",COUNTIFS('Results Log'!$A$5:$A$404,A38,'Results Log'!$B$5:$B$404,"Expected"))
A39: PRK-V05 | B39: Parking Obstruction | C39: Car parked partially inside the zone | D39: Mid | E39: Afternoon | F39: 6–7 min | G39: Main | H39: Not recorded | L39: Not run | M39: No | N39: =IF(A39="","",COUNTIFS('Results Log'!$A$5:$A$404,A39,'Results Log'!$B$5:$B$404,"Expected"))
A40: PRK-L01 | B40: Parking Obstruction | C40: Car stops ~2 min, then leaves | D40: Mid | E40: Day | F40: 6–7 min | G40: Main | H40: Not recorded | L40: Not run | M40: No | N40: =IF(A40="","",COUNTIFS('Results Log'!$A$5:$A$404,A40,'Results Log'!$B$5:$B$404,"Expected"))
A41: PRK-L02 | B41: Parking Obstruction | C41: Tricycle loading/unloading ~3 min | D41: Mid | E41: Afternoon | F41: 6–7 min | G41: Main | H41: Not recorded | L41: Not run | M41: No | N41: =IF(A41="","",COUNTIFS('Results Log'!$A$5:$A$404,A41,'Results Log'!$B$5:$B$404,"Expected"))
A42: PRK-L03 | B42: Parking Obstruction | C42: Car drives through the zone without stopping | D42: Mid | E42: Day | F42: 6–7 min | G42: Main | H42: Not recorded | L42: Not run | M42: No | N42: =IF(A42="","",COUNTIFS('Results Log'!$A$5:$A$404,A42,'Results Log'!$B$5:$B$404,"Expected"))
A43: PRK-L04 | B43: Parking Obstruction | C43: Car parked just outside the zone for 6 min | D43: Mid | E43: Day | F43: 6–7 min | G43: Main | H43: Not recorded | L43: Not run | M43: No | N43: =IF(A43="","",COUNTIFS('Results Log'!$A$5:$A$404,A43,'Results Log'!$B$5:$B$404,"Expected"))
A44: PRK-L05 | B44: Parking Obstruction | C44: Motorcycle stops 4 min 30 s, then leaves | D44: Mid | E44: Night | F44: 6–7 min | G44: Main | H44: Not recorded | L44: Not run | M44: No | N44: =IF(A44="","",COUNTIFS('Results Log'!$A$5:$A$404,A44,'Results Log'!$B$5:$B$404,"Expected"))
A45: HLD-V01 | B45: Holdup | C45: Attacker approaches victim from the front with a knife | D45: Near | E45: Day | F45: 1 min | G45: Main | H45: Not recorded | L45: Not run | M45: No | N45: =IF(A45="","",COUNTIFS('Results Log'!$A$5:$A$404,A45,'Results Log'!$B$5:$B$404,"Expected"))
A46: HLD-V02 | B46: Holdup | C46: Attacker approaches victim from behind with a knife | D46: Near | E46: Day | F46: 1 min | G46: Main | H46: Not recorded | L46: Not run | M46: No | N46: =IF(A46="","",COUNTIFS('Results Log'!$A$5:$A$404,A46,'Results Log'!$B$5:$B$404,"Expected"))
A47: HLD-V03 | B47: Holdup | C47: Two attackers corner one victim, knife shown | D47: Mid | E47: Day | F47: 1 min | G47: Main | H47: Not recorded | L47: Not run | M47: No | N47: =IF(A47="","",COUNTIFS('Results Log'!$A$5:$A$404,A47,'Results Log'!$B$5:$B$404,"Expected"))
A48: HLD-V04 | B48: Holdup | C48: Knife hidden, then revealed close to victim | D48: Near | E48: Afternoon | F48: 1 min | G48: Main | H48: Not recorded | L48: Not run | M48: No | N48: =IF(A48="","",COUNTIFS('Results Log'!$A$5:$A$404,A48,'Results Log'!$B$5:$B$404,"Expected"))
... A59: HLD-L05 | B59: Holdup | C59: Person pointing an umbrella or phone toward another | D59: Mid | E59: Day | F59: 1 min | G59: Main | H59: Not recorded | L59: Not run | M59: No | N59: =IF(A59="","",COUNTIFS('Results Log'!$A$5:$A$404,A59,'Results Log'!$B$5:$B$404,"Expected"))
N60: =IF(A60="","",COUNTIFS('Results Log'!$A$5:$A$404,A60,'Results Log'!$B$5:$B$404,"Expected"))
N61: =IF(A61="","",COUNTIFS('Results Log'!$A$5:$A$404,A61,'Results Log'!$B$5:$B$404,"Expected"))
N62: =IF(A62="","",COUNTIFS('Results Log'!$A$5:$A$404,A62,'Results Log'!$B$5:$B$404,"Expected"))
N63: =IF(A63="","",COUNTIFS('Results Log'!$A$5:$A$404,A63,'Results Log'!$B$5:$B$404,"Expected"))
N64: =IF(A64="","",COUNTIFS('Results Log'!$A$5:$A$404,A64,'Results Log'!$B$5:$B$404,"Expected"))
N65: =IF(A65="","",COUNTIFS('Results Log'!$A$5:$A$404,A65,'Results Log'!$B$5:$B$404,"Expected"))
N66: =IF(A66="","",COUNTIFS('Results Log'!$A$5:$A$404,A66,'Results Log'!$B$5:$B$404,"Expected"))
N67: =IF(A67="","",COUNTIFS('Results Log'!$A$5:$A$404,A67,'Results Log'!$B$5:$B$404,"Expected"))
...

Sheet Results Log
A1: Results Log — one row per answer-key item or unmatched alert
A2: 'Expected' rows = your answer key (typed BEFORE detection). 'Unmatched alert' rows = alerts that matched no answer-key row (tagged by a reviewer). Times in SECONDS of video time.
A4: Clip ID | B4: Row type | C4: Violation type | D4: Kind | E4: Instance # | F4: Who / description | G4: Set | H4: Action start (sec) | I4: Waiting time (sec) | J4: Deadline (sec) | K4: Matched alert ID | L4: Alert time (sec) | M4: Highest status | N4: Delay (sec) | O4: AI checker | P4: Tag | Q4: OUTCOME | R4: Alerted instead | S4: Distance | T4: Time of day | U4: Added after run | V4: Miss / FP reason | W4: Reviewer | X4: Notes | Y4: Tool outcome | Z4: Check | AA4: Run ID
A5: SMK-V01 | B5: Expected | C5: Smoking | D5: Violation | E5: 1 | F5: man at the curb | G5: Main | H5: 5 | I5: =IF(B5<>"Expected","",IF(C5="Parking Obstruction",IF(G5="Validation",Settings!$B$9,Settings!$B$8),IF(C5="Drinking",IF(G5="Validation",Settings!$B$11,Settings!$B$10),0))) | J5: =IF(OR(B5<>"Expected",D5<>"Violation",H5=""),"",H5+I5+Settings!$B$5) | K5: E0001 | L5: 6.5 | M5: Likely | N5: =IF(AND(B5="Expected",D5="Violation",K5<>"",ISNUMBER(L5),ISNUMBER(H5)),L5-H5-I5,"") | O5: Disagrees | Q5: =IF(A5="","",IF(B5="Expected",IF(D5="Violation",IF(H5="","Needs start",IF(AND(K5<>"",OR(M5<>"Monitoring",Settings!$B$7="Yes"),ISNUMBER(L5),L5<=J5),"TP","FN")),IF(AND(K5<>"",OR(M5<>"Monitoring",Settings!$B$7="Yes")),"FP","TN")),IF(P5="","Needs tag",IF(OR(P5="False alarm",P5="Unscripted – false alarm"),"FP",IF(P5="Duplicate","Duplicate",IF(P5="Late (real act)","Late","Excluded")))))) | S5: Near | T5: Day | U5: No | W5: Tester | Y5: TP | Z5: =IF(OR(Y5="",Q5=""),"",IF(Y5=Q5,"OK","MISMATCH")) | AA5: 20261017-235836-0b0358
A6: PRK-V01 | B6: Expected | C6: Parking Obstruction | D6: Violation | E6: 1 | F6: vehicle | G6: Main | H6: 5 | I6: =IF(B6<>"Expected","",IF(C6="Parking Obstruction",IF(G6="Validation",Settings!$B$9,Settings!$B$8),IF(C6="Drinking",IF(G6="Validation",Settings!$B$11,Settings!$B$10),0))) | J6: =IF(OR(B6<>"Expected",D6<>"Violation",H6=""),"",H6+I6+Settings!$B$5) | N6: =IF(AND(B6="Expected",D6="Violation",K6<>"",ISNUMBER(L6),ISNUMBER(H6)),L6-H6-I6,"") | Q6: =IF(A6="","",IF(B6="Expected",IF(D6="Violation",IF(H6="","Needs start",IF(AND(K6<>"",OR(M6<>"Monitoring",Settings!$B$7="Yes"),ISNUMBER(L6),L6<=J6),"TP","FN")),IF(AND(K6<>"",OR(M6<>"Monitoring",Settings!$B$7="Yes")),"FP","TN")),IF(P6="","Needs tag",IF(OR(P6="False alarm",P6="Unscripted – false alarm"),"FP",IF(P6="Duplicate","Duplicate",IF(P6="Late (real act)","Late","Excluded")))))) | R6: Smoking | S6: Mid | T6: Day | U6: No | Y6: FN | Z6: =IF(OR(Y6="",Q6=""),"",IF(Y6=Q6,"OK","MISMATCH")) | AA6: 20261017-234601-13cb6a
A7: PRK-V01 | B7: Unmatched alert | C7: Smoking | G7: Main | I7: =IF(B7<>"Expected","",IF(C7="Parking Obstruction",IF(G7="Validation",Settings!$B$9,Settings!$B$8),IF(C7="Drinking",IF(G7="Validation",Settings!$B$11,Settings!$B$10),0))) | J7: =IF(OR(B7<>"Expected",D7<>"Violation",H7=""),"",H7+I7+Settings!$B$5) | K7: E0001 | L7: 7.2 | M7: Likely | N7: =IF(AND(B7="Expected",D7="Violation",K7<>"",ISNUMBER(L7),ISNUMBER(H7)),L7-H7-I7,"") | O7: Disagrees | Q7: =IF(A7="","",IF(B7="Expected",IF(D7="Violation",IF(H7="","Needs start",IF(AND(K7<>"",OR(M7<>"Monitoring",Settings!$B$7="Yes"),ISNUMBER(L7),L7<=J7),"TP","FN")),IF(AND(K7<>"",OR(M7<>"Monitoring",Settings!$B$7="Yes")),"FP","TN")),IF(P7="","Needs tag",IF(OR(P7="False alarm",P7="Unscripted – false alarm"),"FP",IF(P7="Duplicate","Duplicate",IF(P7="Late (real act)","Late","Excluded")))))) | S7: Mid | T7: Day | Y7: Needs tag | Z7: =IF(OR(Y7="",Q7=""),"",IF(Y7=Q7,"OK","MISMATCH")) | AA7: 20261017-234601-13cb6a
A8: PRK-V02 | B8: Expected | C8: Parking Obstruction | D8: Violation | E8: 1 | F8: motorcycle at the shop | G8: Main | H8: 2 | I8: =IF(B8<>"Expected","",IF(C8="Parking Obstruction",IF(G8="Validation",Settings!$B$9,Settings!$B$8),IF(C8="Drinking",IF(G8="Validation",Settings!$B$11,Settings!$B$10),0))) | J8: =IF(OR(B8<>"Expected",D8<>"Violation",H8=""),"",H8+I8+Settings!$B$5) | K8: E0003 | L8: 40 | M8: Likely | N8: =IF(AND(B8="Expected",D8="Violation",K8<>"",ISNUMBER(L8),ISNUMBER(H8)),L8-H8-I8,"") | O8: Not run | Q8: =IF(A8="","",IF(B8="Expected",IF(D8="Violation",IF(H8="","Needs start",IF(AND(K8<>"",OR(M8<>"Monitoring",Settings!$B$7="Yes"),ISNUMBER(L8),L8<=J8),"TP","FN")),IF(AND(K8<>"",OR(M8<>"Monitoring",Settings!$B$7="Yes")),"FP","TN")),IF(P8="","Needs tag",IF(OR(P8="False alarm",P8="Unscripted – false alarm"),"FP",IF(P8="Duplicate","Duplicate",IF(P8="Late (real act)","Late","Excluded")))))) | S8: Mid | T8: Day | U8: No | Y8: TP | Z8: =IF(OR(Y8="",Q8=""),"",IF(Y8=Q8,"OK","MISMATCH")) | AA8: 20261018-001825-c75439
I9: =IF(B9<>"Expected","",IF(C9="Parking Obstruction",IF(G9="Validation",Settings!$B$9,Settings!$B$8),IF(C9="Drinking",IF(G9="Validation",Settings!$B$11,Settings!$B$10),0))) | J9: =IF(OR(B9<>"Expected",D9<>"Violation",H9=""),"",H9+I9+Settings!$B$5) | N9: =IF(AND(B9="Expected",D9="Violation",K9<>"",ISNUMBER(L9),ISNUMBER(H9)),L9-H9-I9,"") | Q9: =IF(A9="","",IF(B9="Expected",IF(D9="Violation",IF(H9="","Needs start",IF(AND(K9<>"",OR(M9<>"Monitoring",Settings!$B$7="Yes"),ISNUMBER(L9),L9<=J9),"TP","FN")),IF(AND(K9<>"",OR(M9<>"Monitoring",Settings!$B$7="Yes")),"FP","TN")),IF(P9="","Needs tag",IF(OR(P9="False alarm",P9="Unscripted – false alarm"),"FP",IF(P9="Duplicate","Duplicate",IF(P9="Late (real act)","Late","Excluded")))))) | Z9: =IF(OR(Y9="",Q9=""),"",IF(Y9=Q9,"OK","MISMATCH"))
I10: =IF(B10<>"Expected","",IF(C10="Parking Obstruction",IF(G10="Validation",Settings!$B$9,Settings!$B$8),IF(C10="Drinking",IF(G10="Validation",Settings!$B$11,Settings!$B$10),0))) | J10: =IF(OR(B10<>"Expected",D10<>"Violation",H10=""),"",H10+I10+Settings!$B$5) | N10: =IF(AND(B10="Expected",D10="Violation",K10<>"",ISNUMBER(L10),ISNUMBER(H10)),L10-H10-I10,"") | Q10: =IF(A10="","",IF(B10="Expected",IF(D10="Violation",IF(H10="","Needs start",IF(AND(K10<>"",OR(M10<>"Monitoring",Settings!$B$7="Yes"),ISNUMBER(L10),L10<=J10),"TP","FN")),IF(AND(K10<>"",OR(M10<>"Monitoring",Settings!$B$7="Yes")),"FP","TN")),IF(P10="","Needs tag",IF(OR(P10="False alarm",P10="Unscripted – false alarm"),"FP",IF(P10="Duplicate","Duplicate",IF(P10="Late (real act)","Late","Excluded")))))) | Z10: =IF(OR(Y10="",Q10=""),"",IF(Y10=Q10,"OK","MISMATCH"))
I11: =IF(B11<>"Expected","",IF(C11="Parking Obstruction",IF(G11="Validation",Settings!$B$9,Settings!$B$8),IF(C11="Drinking",IF(G11="Validation",Settings!$B$11,Settings!$B$10),0))) | J11: =IF(OR(B11<>"Expected",D11<>"Violation",H11=""),"",H11+I11+Settings!$B$5) | N11: =IF(AND(B11="Expected",D11="Violation",K11<>"",ISNUMBER(L11),ISNUMBER(H11)),L11-H11-I11,"") | Q11: =IF(A11="","",IF(B11="Expected",IF(D11="Violation",IF(H11="","Needs start",IF(AND(K11<>"",OR(M11<>"Monitoring",Settings!$B$7="Yes"),ISNUMBER(L11),L11<=J11),"TP","FN")),IF(AND(K11<>"",OR(M11<>"Monitoring",Settings!$B$7="Yes")),"FP","TN")),IF(P11="","Needs tag",IF(OR(P11="False alarm",P11="Unscripted – false alarm"),"FP",IF(P11="Duplicate","Duplicate",IF(P11="Late (real act)","Late","Excluded")))))) | Z11: =IF(OR(Y11="",Q11=""),"",IF(Y11=Q11,"OK","MISMATCH"))
I12: =IF(B12<>"Expected","",IF(C12="Parking Obstruction",IF(G12="Validation",Settings!$B$9,Settings!$B$8),IF(C12="Drinking",IF(G12="Validation",Settings!$B$11,Settings!$B$10),0))) | J12: =IF(OR(B12<>"Expected",D12<>"Violation",H12=""),"",H12+I12+Settings!$B$5) | N12: =IF(AND(B12="Expected",D12="Violation",K12<>"",ISNUMBER(L12),ISNUMBER(H12)),L12-H12-I12,"") | Q12: =IF(A12="","",IF(B12="Expected",IF(D12="Violation",IF(H12="","Needs start",IF(AND(K12<>"",OR(M12<>"Monitoring",Settings!$B$7="Yes"),ISNUMBER(L12),L12<=J12),"TP","FN")),IF(AND(K12<>"",OR(M12<>"Monitoring",Settings!$B$7="Yes")),"FP","TN")),IF(P12="","Needs tag",IF(OR(P12="False alarm",P12="Unscripted – false alarm"),"FP",IF(P12="Duplicate","Duplicate",IF(P12="Late (real act)","Late","Excluded")))))) | Z12: =IF(OR(Y12="",Q12=""),"",IF(Y12=Q12,"OK","MISMATCH"))
I13: =IF(B13<>"Expected","",IF(C13="Parking Obstruction",IF(G13="Validation",Settings!$B$9,Settings!$B$8),IF(C13="Drinking",IF(G13="Validation",Settings!$B$11,Settings!$B$10),0))) | J13: =IF(OR(B13<>"Expected",D13<>"Violation",H13=""),"",H13+I13+Settings!$B$5) | N13: =IF(AND(B13="Expected",D13="Violation",K13<>"",ISNUMBER(L13),ISNUMBER(H13)),L13-H13-I13,"") | Q13: =IF(A13="","",IF(B13="Expected",IF(D13="Violation",IF(H13="","Needs start",IF(AND(K13<>"",OR(M13<>"Monitoring",Settings!$B$7="Yes"),ISNUMBER(L13),L13<=J13),"TP","FN")),IF(AND(K13<>"",OR(M13<>"Monitoring",Settings!$B$7="Yes")),"FP","TN")),IF(P13="","Needs tag",IF(OR(P13="False alarm",P13="Unscripted – false alarm"),"FP",IF(P13="Duplicate","Duplicate",IF(P13="Late (real act)","Late","Excluded")))))) | Z13: =IF(OR(Y13="",Q13=""),"",IF(Y13=Q13,"OK","MISMATCH"))
I14: =IF(B14<>"Expected","",IF(C14="Parking Obstruction",IF(G14="Validation",Settings!$B$9,Settings!$B$8),IF(C14="Drinking",IF(G14="Validation",Settings!$B$11,Settings!$B$10),0))) | J14: =IF(OR(B14<>"Expected",D14<>"Violation",H14=""),"",H14+I14+Settings!$B$5) | N14: =IF(AND(B14="Expected",D14="Violation",K14<>"",ISNUMBER(L14),ISNUMBER(H14)),L14-H14-I14,"") | Q14: =IF(A14="","",IF(B14="Expected",IF(D14="Violation",IF(H14="","Needs start",IF(AND(K14<>"",OR(M14<>"Monitoring",Settings!$B$7="Yes"),ISNUMBER(L14),L14<=J14),"TP","FN")),IF(AND(K14<>"",OR(M14<>"Monitoring",Settings!$B$7="Yes")),"FP","TN")),IF(P14="","Needs tag",IF(OR(P14="False alarm",P14="Unscripted – false alarm"),"FP",IF(P14="Duplicate","Duplicate",IF(P14="Late (real act)","Late","Excluded")))))) | Z14: =IF(OR(Y14="",Q14=""),"",IF(Y14=Q14,"OK","MISMATCH"))
I15: =IF(B15<>"Expected","",IF(C15="Parking Obstruction",IF(G15="Validation",Settings!$B$9,Settings!$B$8),IF(C15="Drinking",IF(G15="Validation",Settings!$B$11,Settings!$B$10),0))) | J15: =IF(OR(B15<>"Expected",D15<>"Violation",H15=""),"",H15+I15+Settings!$B$5) | N15: =IF(AND(B15="Expected",D15="Violation",K15<>"",ISNUMBER(L15),ISNUMBER(H15)),L15-H15-I15,"") | Q15: =IF(A15="","",IF(B15="Expected",IF(D15="Violation",IF(H15="","Needs start",IF(AND(K15<>"",OR(M15<>"Monitoring",Settings!$B$7="Yes"),ISNUMBER(L15),L15<=J15),"TP","FN")),IF(AND(K15<>"",OR(M15<>"Monitoring",Settings!$B$7="Yes")),"FP","TN")),IF(P15="","Needs tag",IF(OR(P15="False alarm",P15="Unscripted – false alarm"),"FP",IF(P15="Duplicate","Duplicate",IF(P15="Late (real act)","Late","Excluded")))))) | Z15: =IF(OR(Y15="",Q15=""),"",IF(Y15=Q15,"OK","MISMATCH"))
I16: =IF(B16<>"Expected","",IF(C16="Parking Obstruction",IF(G16="Validation",Settings!$B$9,Settings!$B$8),IF(C16="Drinking",IF(G16="Validation",Settings!$B$11,Settings!$B$10),0))) | J16: =IF(OR(B16<>"Expected",D16<>"Violation",H16=""),"",H16+I16+Settings!$B$5) | N16: =IF(AND(B16="Expected",D16="Violation",K16<>"",ISNUMBER(L16),ISNUMBER(H16)),L16-H16-I16,"") | Q16: =IF(A16="","",IF(B16="Expected",IF(D16="Violation",IF(H16="","Needs start",IF(AND(K16<>"",OR(M16<>"Monitoring",Settings!$B$7="Yes"),ISNUMBER(L16),L16<=J16),"TP","FN")),IF(AND(K16<>"",OR(M16<>"Monitoring",Settings!$B$7="Yes")),"FP","TN")),IF(P16="","Needs tag",IF(OR(P16="False alarm",P16="Unscripted – false alarm"),"FP",IF(P16="Duplicate","Duplicate",IF(P16="Late (real act)","Late","Excluded")))))) | Z16: =IF(OR(Y16="",Q16=""),"",IF(Y16=Q16,"OK","MISMATCH"))
I17: =IF(B17<>"Expected","",IF(C17="Parking Obstruction",IF(G17="Validation",Settings!$B$9,Settings!$B$8),IF(C17="Drinking",IF(G17="Validation",Settings!$B$11,Settings!$B$10),0))) | J17: =IF(OR(B17<>"Expected",D17<>"Violation",H17=""),"",H17+I17+Settings!$B$5) | N17: =IF(AND(B17="Expected",D17="Violation",K17<>"",ISNUMBER(L17),ISNUMBER(H17)),L17-H17-I17,"") | Q17: =IF(A17="","",IF(B17="Expected",IF(D17="Violation",IF(H17="","Needs start",IF(AND(K17<>"",OR(M17<>"Monitoring",Settings!$B$7="Yes"),ISNUMBER(L17),L17<=J17),"TP","FN")),IF(AND(K17<>"",OR(M17<>"Monitoring",Settings!$B$7="Yes")),"FP","TN")),IF(P17="","Needs tag",IF(OR(P17="False alarm",P17="Unscripted – false alarm"),"FP",IF(P17="Duplicate","Duplicate",IF(P17="Late (real act)","Late","Excluded")))))) | Z17: =IF(OR(Y17="",Q17=""),"",IF(Y17=Q17,"OK","MISMATCH"))
I18: =IF(B18<>"Expected","",IF(C18="Parking Obstruction",IF(G18="Validation",Settings!$B$9,Settings!$B$8),IF(C18="Drinking",IF(G18="Validation",Settings!$B$11,Settings!$B$10),0))) | J18: =IF(OR(B18<>"Expected",D18<>"Violation",H18=""),"",H18+I18+Settings!$B$5) | N18: =IF(AND(B18="Expected",D18="Violation",K18<>"",ISNUMBER(L18),ISNUMBER(H18)),L18-H18-I18,"") | Q18: =IF(A18="","",IF(B18="Expected",IF(D18="Violation",IF(H18="","Needs start",IF(AND(K18<>"",OR(M18<>"Monitoring",Settings!$B$7="Yes"),ISNUMBER(L18),L18<=J18),"TP","FN")),IF(AND(K18<>"",OR(M18<>"Monitoring",Settings!$B$7="Yes")),"FP","TN")),IF(P18="","Needs tag",IF(OR(P18="False alarm",P18="Unscripted – false alarm"),"FP",IF(P18="Duplicate","Duplicate",IF(P18="Late (real act)","Late","Excluded")))))) | Z18: =IF(OR(Y18="",Q18=""),"",IF(Y18=Q18,"OK","MISMATCH"))
I19: =IF(B19<>"Expected","",IF(C19="Parking Obstruction",IF(G19="Validation",Settings!$B$9,Settings!$B$8),IF(C19="Drinking",IF(G19="Validation",Settings!$B$11,Settings!$B$10),0))) | J19: =IF(OR(B19<>"Expected",D19<>"Violation",H19=""),"",H19+I19+Settings!$B$5) | N19: =IF(AND(B19="Expected",D19="Violation",K19<>"",ISNUMBER(L19),ISNUMBER(H19)),L19-H19-I19,"") | Q19: =IF(A19="","",IF(B19="Expected",IF(D19="Violation",IF(H19="","Needs start",IF(AND(K19<>"",OR(M19<>"Monitoring",Settings!$B$7="Yes"),ISNUMBER(L19),L19<=J19),"TP","FN")),IF(AND(K19<>"",OR(M19<>"Monitoring",Settings!$B$7="Yes")),"FP","TN")),IF(P19="","Needs tag",IF(OR(P19="False alarm",P19="Unscripted – false alarm"),"FP",IF(P19="Duplicate","Duplicate",IF(P19="Late (real act)","Late","Excluded")))))) | Z19: =IF(OR(Y19="",Q19=""),"",IF(Y19=Q19,"OK","MISMATCH"))
I20: =IF(B20<>"Expected","",IF(C20="Parking Obstruction",IF(G20="Validation",Settings!$B$9,Settings!$B$8),IF(C20="Drinking",IF(G20="Validation",Settings!$B$11,Settings!$B$10),0))) | J20: =IF(OR(B20<>"Expected",D20<>"Violation",H20=""),"",H20+I20+Settings!$B$5) | N20: =IF(AND(B20="Expected",D20="Violation",K20<>"",ISNUMBER(L20),ISNUMBER(H20)),L20-H20-I20,"") | Q20: =IF(A20="","",IF(B20="Expected",IF(D20="Violation",IF(H20="","Needs start",IF(AND(K20<>"",OR(M20<>"Monitoring",Settings!$B$7="Yes"),ISNUMBER(L20),L20<=J20),"TP","FN")),IF(AND(K20<>"",OR(M20<>"Monitoring",Settings!$B$7="Yes")),"FP","TN")),IF(P20="","Needs tag",IF(OR(P20="False alarm",P20="Unscripted – false alarm"),"FP",IF(P20="Duplicate","Duplicate",IF(P20="Late (real act)","Late","Excluded")))))) | Z20: =IF(OR(Y20="",Q20=""),"",IF(Y20=Q20,"OK","MISMATCH"))
... I404: =IF(B404<>"Expected","",IF(C404="Parking Obstruction",IF(G404="Validation",Settings!$B$9,Settings!$B$8),IF(C404="Drinking",IF(G404="Validation",Settings!$B$11,Settings!$B$10),0))) | J404: =IF(OR(B404<>"Expected",D404<>"Violation",H404=""),"",H404+I404+Settings!$B$5) | N404: =IF(AND(B404="Expected",D404="Violation",K404<>"",ISNUMBER(L404),ISNUMBER(H404)),L404-H404-I404,"") | Q404: =IF(A404="","",IF(B404="Expected",IF(D404="Violation",IF(H404="","Needs start",IF(AND(K404<>"",OR(M404<>"Monitoring",Settings!$B$7="Yes"),ISNUMBER(L404),L404<=J404),"TP","FN")),IF(AND(K404<>"",OR(M404<>"Monitoring",Settings!$B$7="Yes")),"FP","TN")),IF(P404="","Needs tag",IF(OR(P404="False alarm",P404="Unscripted – false alarm"),"FP",IF(P404="Duplicate","Duplicate",IF(P404="Late (real act)","Late","Excluded")))))) | Z404: =IF(OR(Y404="",Q404=""),"",IF(Y404=Q404,"OK","MISMATCH"))

Sheet Summary
A1: Summary — System Accuracy (Main set)
A2: Auto-calculated from Results Log, Main set only. '–' = no data yet. Validation set is reported in its own sheet.
A4: Violation | B4: Real acts scored | C4: TP | D4: FN | E4: TN | F4: FP (look-alike / no violation) | G4: FP (false alarm on actors) | H4: FP (unscripted) | I4: FP total | J4: Accuracy | K4: Precision | L4: Recall | M4: F1 | N4: Avg delay (s) | O4: Duplicates | P4: Late detections | Q4: Unscripted real (excluded) | R4: Needs tag
A5: Smoking | B5: =C5+D5 | C5: =COUNTIFS('Results Log'!$G$5:$G$404,"Main",'Results Log'!$B$5:$B$404,"Expected",'Results Log'!$C$5:$C$404,"Smoking",'Results Log'!$Q$5:$Q$404,"TP") | D5: =COUNTIFS('Results Log'!$G$5:$G$404,"Main",'Results Log'!$B$5:$B$404,"Expected",'Results Log'!$C$5:$C$404,"Smoking",'Results Log'!$Q$5:$Q$404,"FN") | E5: =COUNTIFS('Results Log'!$G$5:$G$404,"Main",'Results Log'!$B$5:$B$404,"Expected",'Results Log'!$C$5:$C$404,"Smoking",'Results Log'!$Q$5:$Q$404,"TN") | F5: =COUNTIFS('Results Log'!$G$5:$G$404,"Main",'Results Log'!$B$5:$B$404,"Expected",'Results Log'!$C$5:$C$404,"Smoking",'Results Log'!$Q$5:$Q$404,"FP") | G5: =COUNTIFS('Results Log'!$G$5:$G$404,"Main",'Results Log'!$B$5:$B$404,"Unmatched alert",'Results Log'!$C$5:$C$404,"Smoking",'Results Log'!$P$5:$P$404,"False alarm") | H5: =COUNTIFS('Results Log'!$G$5:$G$404,"Main",'Results Log'!$B$5:$B$404,"Unmatched alert",'Results Log'!$C$5:$C$404,"Smoking",'Results Log'!$P$5:$P$404,"Unscripted – false alarm") | I5: =F5+G5+H5 | J5: =IFERROR((C5+E5)/(C5+D5+E5+I5),"–") | K5: =IFERROR(C5/(C5+I5),"–") | L5: =IFERROR(C5/(C5+D5),"–") | M5: =IFERROR(2*K5*L5/(K5+L5),"–") | N5: =IFERROR(AVERAGEIFS('Results Log'!$N$5:$N$404,'Results Log'!$G$5:$G$404,"Main",'Results Log'!$Q$5:$Q$404,"TP",'Results Log'!$C$5:$C$404,"Smoking"),"–") | O5: =COUNTIFS('Results Log'!$G$5:$G$404,"Main",'Results Log'!$B$5:$B$404,"Unmatched alert",'Results Log'!$C$5:$C$404,"Smoking",'Results Log'!$P$5:$P$404,"Duplicate") | P5: =COUNTIFS('Results Log'!$G$5:$G$404,"Main",'Results Log'!$B$5:$B$404,"Unmatched alert",'Results Log'!$C$5:$C$404,"Smoking",'Results Log'!$P$5:$P$404,"Late (real act)") | Q5: =COUNTIFS('Results Log'!$G$5:$G$404,"Main",'Results Log'!$B$5:$B$404,"Unmatched alert",'Results Log'!$C$5:$C$404,"Smoking",'Results Log'!$P$5:$P$404,"Unscripted – real violation") | R5: =COUNTIFS('Results Log'!$G$5:$G$404,"Main",'Results Log'!$C$5:$C$404,"Smoking",'Results Log'!$Q$5:$Q$404,"Needs tag")+COUNTIFS('Results Log'!$G$5:$G$404,"Main",'Results Log'!$C$5:$C$404,"Smoking",'Results Log'!$Q$5:$Q$404,"Needs start")
A6: Drinking | B6: =C6+D6 | C6: =COUNTIFS('Results Log'!$G$5:$G$404,"Main",'Results Log'!$B$5:$B$404,"Expected",'Results Log'!$C$5:$C$404,"Drinking",'Results Log'!$Q$5:$Q$404,"TP") | D6: =COUNTIFS('Results Log'!$G$5:$G$404,"Main",'Results Log'!$B$5:$B$404,"Expected",'Results Log'!$C$5:$C$404,"Drinking",'Results Log'!$Q$5:$Q$404,"FN") | E6: =COUNTIFS('Results Log'!$G$5:$G$404,"Main",'Results Log'!$B$5:$B$404,"Expected",'Results Log'!$C$5:$C$404,"Drinking",'Results Log'!$Q$5:$Q$404,"TN") | F6: =COUNTIFS('Results Log'!$G$5:$G$404,"Main",'Results Log'!$B$5:$B$404,"Expected",'Results Log'!$C$5:$C$404,"Drinking",'Results Log'!$Q$5:$Q$404,"FP") | G6: =COUNTIFS('Results Log'!$G$5:$G$404,"Main",'Results Log'!$B$5:$B$404,"Unmatched alert",'Results Log'!$C$5:$C$404,"Drinking",'Results Log'!$P$5:$P$404,"False alarm") | H6: =COUNTIFS('Results Log'!$G$5:$G$404,"Main",'Results Log'!$B$5:$B$404,"Unmatched alert",'Results Log'!$C$5:$C$404,"Drinking",'Results Log'!$P$5:$P$404,"Unscripted – false alarm") | I6: =F6+G6+H6 | J6: =IFERROR((C6+E6)/(C6+D6+E6+I6),"–") | K6: =IFERROR(C6/(C6+I6),"–") | L6: =IFERROR(C6/(C6+D6),"–") | M6: =IFERROR(2*K6*L6/(K6+L6),"–") | N6: =IFERROR(AVERAGEIFS('Results Log'!$N$5:$N$404,'Results Log'!$G$5:$G$404,"Main",'Results Log'!$Q$5:$Q$404,"TP",'Results Log'!$C$5:$C$404,"Drinking"),"–") | O6: =COUNTIFS('Results Log'!$G$5:$G$404,"Main",'Results Log'!$B$5:$B$404,"Unmatched alert",'Results Log'!$C$5:$C$404,"Drinking",'Results Log'!$P$5:$P$404,"Duplicate") | P6: =COUNTIFS('Results Log'!$G$5:$G$404,"Main",'Results Log'!$B$5:$B$404,"Unmatched alert",'Results Log'!$C$5:$C$404,"Drinking",'Results Log'!$P$5:$P$404,"Late (real act)") | Q6: =COUNTIFS('Results Log'!$G$5:$G$404,"Main",'Results Log'!$B$5:$B$404,"Unmatched alert",'Results Log'!$C$5:$C$404,"Drinking",'Results Log'!$P$5:$P$404,"Unscripted – real violation") | R6: =COUNTIFS('Results Log'!$G$5:$G$404,"Main",'Results Log'!$C$5:$C$404,"Drinking",'Results Log'!$Q$5:$Q$404,"Needs tag")+COUNTIFS('Results Log'!$G$5:$G$404,"Main",'Results Log'!$C$5:$C$404,"Drinking",'Results Log'!$Q$5:$Q$404,"Needs start")
A7: Parking Obstruction | B7: =C7+D7 | C7: =COUNTIFS('Results Log'!$G$5:$G$404,"Main",'Results Log'!$B$5:$B$404,"Expected",'Results Log'!$C$5:$C$404,"Parking Obstruction",'Results Log'!$Q$5:$Q$404,"TP") | D7: =COUNTIFS('Results Log'!$G$5:$G$404,"Main",'Results Log'!$B$5:$B$404,"Expected",'Results Log'!$C$5:$C$404,"Parking Obstruction",'Results Log'!$Q$5:$Q$404,"FN") | E7: =COUNTIFS('Results Log'!$G$5:$G$404,"Main",'Results Log'!$B$5:$B$404,"Expected",'Results Log'!$C$5:$C$404,"Parking Obstruction",'Results Log'!$Q$5:$Q$404,"TN") | F7: =COUNTIFS('Results Log'!$G$5:$G$404,"Main",'Results Log'!$B$5:$B$404,"Expected",'Results Log'!$C$5:$C$404,"Parking Obstruction",'Results Log'!$Q$5:$Q$404,"FP") | G7: =COUNTIFS('Results Log'!$G$5:$G$404,"Main",'Results Log'!$B$5:$B$404,"Unmatched alert",'Results Log'!$C$5:$C$404,"Parking Obstruction",'Results Log'!$P$5:$P$404,"False alarm") | H7: =COUNTIFS('Results Log'!$G$5:$G$404,"Main",'Results Log'!$B$5:$B$404,"Unmatched alert",'Results Log'!$C$5:$C$404,"Parking Obstruction",'Results Log'!$P$5:$P$404,"Unscripted – false alarm") | I7: =F7+G7+H7 | J7: =IFERROR((C7+E7)/(C7+D7+E7+I7),"–") | K7: =IFERROR(C7/(C7+I7),"–") | L7: =IFERROR(C7/(C7+D7),"–") | M7: =IFERROR(2*K7*L7/(K7+L7),"–") | N7: =IFERROR(AVERAGEIFS('Results Log'!$N$5:$N$404,'Results Log'!$G$5:$G$404,"Main",'Results Log'!$Q$5:$Q$404,"TP",'Results Log'!$C$5:$C$404,"Parking Obstruction"),"–") | O7: =COUNTIFS('Results Log'!$G$5:$G$404,"Main",'Results Log'!$B$5:$B$404,"Unmatched alert",'Results Log'!$C$5:$C$404,"Parking Obstruction",'Results Log'!$P$5:$P$404,"Duplicate") | P7: =COUNTIFS('Results Log'!$G$5:$G$404,"Main",'Results Log'!$B$5:$B$404,"Unmatched alert",'Results Log'!$C$5:$C$404,"Parking Obstruction",'Results Log'!$P$5:$P$404,"Late (real act)") | Q7: =COUNTIFS('Results Log'!$G$5:$G$404,"Main",'Results Log'!$B$5:$B$404,"Unmatched alert",'Results Log'!$C$5:$C$404,"Parking Obstruction",'Results Log'!$P$5:$P$404,"Unscripted – real violation") | R7: =COUNTIFS('Results Log'!$G$5:$G$404,"Main",'Results Log'!$C$5:$C$404,"Parking Obstruction",'Results Log'!$Q$5:$Q$404,"Needs tag")+COUNTIFS('Results Log'!$G$5:$G$404,"Main",'Results Log'!$C$5:$C$404,"Parking Obstruction",'Results Log'!$Q$5:$Q$404,"Needs start")
A8: Holdup | B8: =C8+D8 | C8: =COUNTIFS('Results Log'!$G$5:$G$404,"Main",'Results Log'!$B$5:$B$404,"Expected",'Results Log'!$C$5:$C$404,"Holdup",'Results Log'!$Q$5:$Q$404,"TP") | D8: =COUNTIFS('Results Log'!$G$5:$G$404,"Main",'Results Log'!$B$5:$B$404,"Expected",'Results Log'!$C$5:$C$404,"Holdup",'Results Log'!$Q$5:$Q$404,"FN") | E8: =COUNTIFS('Results Log'!$G$5:$G$404,"Main",'Results Log'!$B$5:$B$404,"Expected",'Results Log'!$C$5:$C$404,"Holdup",'Results Log'!$Q$5:$Q$404,"TN") | F8: =COUNTIFS('Results Log'!$G$5:$G$404,"Main",'Results Log'!$B$5:$B$404,"Expected",'Results Log'!$C$5:$C$404,"Holdup",'Results Log'!$Q$5:$Q$404,"FP") | G8: =COUNTIFS('Results Log'!$G$5:$G$404,"Main",'Results Log'!$B$5:$B$404,"Unmatched alert",'Results Log'!$C$5:$C$404,"Holdup",'Results Log'!$P$5:$P$404,"False alarm") | H8: =COUNTIFS('Results Log'!$G$5:$G$404,"Main",'Results Log'!$B$5:$B$404,"Unmatched alert",'Results Log'!$C$5:$C$404,"Holdup",'Results Log'!$P$5:$P$404,"Unscripted – false alarm") | I8: =F8+G8+H8 | J8: =IFERROR((C8+E8)/(C8+D8+E8+I8),"–") | K8: =IFERROR(C8/(C8+I8),"–") | L8: =IFERROR(C8/(C8+D8),"–") | M8: =IFERROR(2*K8*L8/(K8+L8),"–") | N8: =IFERROR(AVERAGEIFS('Results Log'!$N$5:$N$404,'Results Log'!$G$5:$G$404,"Main",'Results Log'!$Q$5:$Q$404,"TP",'Results Log'!$C$5:$C$404,"Holdup"),"–") | O8: =COUNTIFS('Results Log'!$G$5:$G$404,"Main",'Results Log'!$B$5:$B$404,"Unmatched alert",'Results Log'!$C$5:$C$404,"Holdup",'Results Log'!$P$5:$P$404,"Duplicate") | P8: =COUNTIFS('Results Log'!$G$5:$G$404,"Main",'Results Log'!$B$5:$B$404,"Unmatched alert",'Results Log'!$C$5:$C$404,"Holdup",'Results Log'!$P$5:$P$404,"Late (real act)") | Q8: =COUNTIFS('Results Log'!$G$5:$G$404,"Main",'Results Log'!$B$5:$B$404,"Unmatched alert",'Results Log'!$C$5:$C$404,"Holdup",'Results Log'!$P$5:$P$404,"Unscripted – real violation") | R8: =COUNTIFS('Results Log'!$G$5:$G$404,"Main",'Results Log'!$C$5:$C$404,"Holdup",'Results Log'!$Q$5:$Q$404,"Needs tag")+COUNTIFS('Results Log'!$G$5:$G$404,"Main",'Results Log'!$C$5:$C$404,"Holdup",'Results Log'!$Q$5:$Q$404,"Needs start")
A9: OVERALL | B9: =C9+D9 | C9: =COUNTIFS('Results Log'!$G$5:$G$404,"Main",'Results Log'!$B$5:$B$404,"Expected",'Results Log'!$Q$5:$Q$404,"TP") | D9: =COUNTIFS('Results Log'!$G$5:$G$404,"Main",'Results Log'!$B$5:$B$404,"Expected",'Results Log'!$Q$5:$Q$404,"FN") | E9: =COUNTIFS('Results Log'!$G$5:$G$404,"Main",'Results Log'!$B$5:$B$404,"Expected",'Results Log'!$Q$5:$Q$404,"TN") | F9: =COUNTIFS('Results Log'!$G$5:$G$404,"Main",'Results Log'!$B$5:$B$404,"Expected",'Results Log'!$Q$5:$Q$404,"FP") | G9: =COUNTIFS('Results Log'!$G$5:$G$404,"Main",'Results Log'!$B$5:$B$404,"Unmatched alert",'Results Log'!$P$5:$P$404,"False alarm") | H9: =COUNTIFS('Results Log'!$G$5:$G$404,"Main",'Results Log'!$B$5:$B$404,"Unmatched alert",'Results Log'!$P$5:$P$404,"Unscripted – false alarm") | I9: =F9+G9+H9 | J9: =IFERROR((C9+E9)/(C9+D9+E9+I9),"–") | K9: =IFERROR(C9/(C9+I9),"–") | L9: =IFERROR(C9/(C9+D9),"–") | M9: =IFERROR(2*K9*L9/(K9+L9),"–") | N9: =IFERROR(AVERAGEIFS('Results Log'!$N$5:$N$404,'Results Log'!$G$5:$G$404,"Main",'Results Log'!$Q$5:$Q$404,"TP"),"–") | O9: =COUNTIFS('Results Log'!$G$5:$G$404,"Main",'Results Log'!$B$5:$B$404,"Unmatched alert",'Results Log'!$P$5:$P$404,"Duplicate") | P9: =COUNTIFS('Results Log'!$G$5:$G$404,"Main",'Results Log'!$B$5:$B$404,"Unmatched alert",'Results Log'!$P$5:$P$404,"Late (real act)") | Q9: =COUNTIFS('Results Log'!$G$5:$G$404,"Main",'Results Log'!$B$5:$B$404,"Unmatched alert",'Results Log'!$P$5:$P$404,"Unscripted – real violation") | R9: =COUNTIFS('Results Log'!$G$5:$G$404,"Main",'Results Log'!$Q$5:$Q$404,"Needs tag")+COUNTIFS('Results Log'!$G$5:$G$404,"Main",'Results Log'!$Q$5:$Q$404,"Needs start")
A11: Clips planned | B11: =COUNTA(Clips!$A$5:$A$154)
A12: Clips done | B12: =COUNTIF(Clips!$L$5:$L$154,"Done")
A13: Clips reviewed | B13: =COUNTIF(Clips!$M$5:$M$154,"Yes")
A14: Progress (reviewed / planned) | B14: =IFERROR(B13/B11,0)
A15: Tool vs sheet mismatches | B15: =COUNTIF('Results Log'!$Z$5:$Z$404,"MISMATCH")
A16: Rows added/edited after run | B16: =COUNTIF('Results Log'!$U$5:$U$404,"Yes")
A17: Settings consistency | B17: =Settings!$B$22&""
A19: Miss / FP reasons (Main set)
A20: Reason | B20: Smoking | C20: Drinking | D20: Parking Obstruction | E20: Holdup | F20: Total
A21: Distance / too small | B21: =COUNTIFS('Results Log'!$V$5:$V$404,$A21,'Results Log'!$C$5:$C$404,"Smoking",'Results Log'!$G$5:$G$404,"Main") | C21: =COUNTIFS('Results Log'!$V$5:$V$404,$A21,'Results Log'!$C$5:$C$404,"Drinking",'Results Log'!$G$5:$G$404,"Main") | D21: =COUNTIFS('Results Log'!$V$5:$V$404,$A21,'Results Log'!$C$5:$C$404,"Parking Obstruction",'Results Log'!$G$5:$G$404,"Main") | E21: =COUNTIFS('Results Log'!$V$5:$V$404,$A21,'Results Log'!$C$5:$C$404,"Holdup",'Results Log'!$G$5:$G$404,"Main") | F21: =SUM(B21:E21)
A22: Occlusion | B22: =COUNTIFS('Results Log'!$V$5:$V$404,$A22,'Results Log'!$C$5:$C$404,"Smoking",'Results Log'!$G$5:$G$404,"Main") | C22: =COUNTIFS('Results Log'!$V$5:$V$404,$A22,'Results Log'!$C$5:$C$404,"Drinking",'Results Log'!$G$5:$G$404,"Main") | D22: =COUNTIFS('Results Log'!$V$5:$V$404,$A22,'Results Log'!$C$5:$C$404,"Parking Obstruction",'Results Log'!$G$5:$G$404,"Main") | E22: =COUNTIFS('Results Log'!$V$5:$V$404,$A22,'Results Log'!$C$5:$C$404,"Holdup",'Results Log'!$G$5:$G$404,"Main") | F22: =SUM(B22:E22)
A23: Lighting / glare | B23: =COUNTIFS('Results Log'!$V$5:$V$404,$A23,'Results Log'!$C$5:$C$404,"Smoking",'Results Log'!$G$5:$G$404,"Main") | C23: =COUNTIFS('Results Log'!$V$5:$V$404,$A23,'Results Log'!$C$5:$C$404,"Drinking",'Results Log'!$G$5:$G$404,"Main") | D23: =COUNTIFS('Results Log'!$V$5:$V$404,$A23,'Results Log'!$C$5:$C$404,"Parking Obstruction",'Results Log'!$G$5:$G$404,"Main") | E23: =COUNTIFS('Results Log'!$V$5:$V$404,$A23,'Results Log'!$C$5:$C$404,"Holdup",'Results Log'!$G$5:$G$404,"Main") | F23: =SUM(B23:E23)
A24: Track ID switch | B24: =COUNTIFS('Results Log'!$V$5:$V$404,$A24,'Results Log'!$C$5:$C$404,"Smoking",'Results Log'!$G$5:$G$404,"Main") | C24: =COUNTIFS('Results Log'!$V$5:$V$404,$A24,'Results Log'!$C$5:$C$404,"Drinking",'Results Log'!$G$5:$G$404,"Main") | D24: =COUNTIFS('Results Log'!$V$5:$V$404,$A24,'Results Log'!$C$5:$C$404,"Parking Obstruction",'Results Log'!$G$5:$G$404,"Main") | E24: =COUNTIFS('Results Log'!$V$5:$V$404,$A24,'Results Log'!$C$5:$C$404,"Holdup",'Results Log'!$G$5:$G$404,"Main") | F24: =SUM(B24:E24)
A25: Alert too late | B25: =COUNTIFS('Results Log'!$V$5:$V$404,$A25,'Results Log'!$C$5:$C$404,"Smoking",'Results Log'!$G$5:$G$404,"Main") | C25: =COUNTIFS('Results Log'!$V$5:$V$404,$A25,'Results Log'!$C$5:$C$404,"Drinking",'Results Log'!$G$5:$G$404,"Main") | D25: =COUNTIFS('Results Log'!$V$5:$V$404,$A25,'Results Log'!$C$5:$C$404,"Parking Obstruction",'Results Log'!$G$5:$G$404,"Main") | E25: =COUNTIFS('Results Log'!$V$5:$V$404,$A25,'Results Log'!$C$5:$C$404,"Holdup",'Results Log'!$G$5:$G$404,"Main") | F25: =SUM(B25:E25)
A26: Wrong type | B26: =COUNTIFS('Results Log'!$V$5:$V$404,$A26,'Results Log'!$C$5:$C$404,"Smoking",'Results Log'!$G$5:$G$404,"Main") | C26: =COUNTIFS('Results Log'!$V$5:$V$404,$A26,'Results Log'!$C$5:$C$404,"Drinking",'Results Log'!$G$5:$G$404,"Main") | D26: =COUNTIFS('Results Log'!$V$5:$V$404,$A26,'Results Log'!$C$5:$C$404,"Parking Obstruction",'Results Log'!$G$5:$G$404,"Main") | E26: =COUNTIFS('Results Log'!$V$5:$V$404,$A26,'Results Log'!$C$5:$C$404,"Holdup",'Results Log'!$G$5:$G$404,"Main") | F26: =SUM(B26:E26)
A27: Look-alike object | B27: =COUNTIFS('Results Log'!$V$5:$V$404,$A27,'Results Log'!$C$5:$C$404,"Smoking",'Results Log'!$G$5:$G$404,"Main") | C27: =COUNTIFS('Results Log'!$V$5:$V$404,$A27,'Results Log'!$C$5:$C$404,"Drinking",'Results Log'!$G$5:$G$404,"Main") | D27: =COUNTIFS('Results Log'!$V$5:$V$404,$A27,'Results Log'!$C$5:$C$404,"Parking Obstruction",'Results Log'!$G$5:$G$404,"Main") | E27: =COUNTIFS('Results Log'!$V$5:$V$404,$A27,'Results Log'!$C$5:$C$404,"Holdup",'Results Log'!$G$5:$G$404,"Main") | F27: =SUM(B27:E27)
A28: Crowd | B28: =COUNTIFS('Results Log'!$V$5:$V$404,$A28,'Results Log'!$C$5:$C$404,"Smoking",'Results Log'!$G$5:$G$404,"Main") | C28: =COUNTIFS('Results Log'!$V$5:$V$404,$A28,'Results Log'!$C$5:$C$404,"Drinking",'Results Log'!$G$5:$G$404,"Main") | D28: =COUNTIFS('Results Log'!$V$5:$V$404,$A28,'Results Log'!$C$5:$C$404,"Parking Obstruction",'Results Log'!$G$5:$G$404,"Main") | E28: =COUNTIFS('Results Log'!$V$5:$V$404,$A28,'Results Log'!$C$5:$C$404,"Holdup",'Results Log'!$G$5:$G$404,"Main") | F28: =SUM(B28:E28)
A29: Other | B29: =COUNTIFS('Results Log'!$V$5:$V$404,$A29,'Results Log'!$C$5:$C$404,"Smoking",'Results Log'!$G$5:$G$404,"Main") | C29: =COUNTIFS('Results Log'!$V$5:$V$404,$A29,'Results Log'!$C$5:$C$404,"Drinking",'Results Log'!$G$5:$G$404,"Main") | D29: =COUNTIFS('Results Log'!$V$5:$V$404,$A29,'Results Log'!$C$5:$C$404,"Parking Obstruction",'Results Log'!$G$5:$G$404,"Main") | E29: =COUNTIFS('Results Log'!$V$5:$V$404,$A29,'Results Log'!$C$5:$C$404,"Holdup",'Results Log'!$G$5:$G$404,"Main") | F29: =SUM(B29:E29)

Sheet Validation
A1: Validation set — real thresholds
A2: Clips run with the real parking threshold (Ord. No. 601) and real inuman duration. Reported separately to show the real rule works.
A4: Violation | B4: Real acts scored | C4: TP | D4: FN | E4: TN | F4: FP (look-alike / no violation) | G4: FP (false alarm on actors) | H4: FP (unscripted) | I4: FP total | J4: Accuracy | K4: Precision | L4: Recall | M4: F1 | N4: Avg delay (s) | O4: Duplicates | P4: Late detections | Q4: Unscripted real (excluded) | R4: Needs tag
A5: Smoking | B5: =C5+D5 | C5: =COUNTIFS('Results Log'!$G$5:$G$404,"Validation",'Results Log'!$B$5:$B$404,"Expected",'Results Log'!$C$5:$C$404,"Smoking",'Results Log'!$Q$5:$Q$404,"TP") | D5: =COUNTIFS('Results Log'!$G$5:$G$404,"Validation",'Results Log'!$B$5:$B$404,"Expected",'Results Log'!$C$5:$C$404,"Smoking",'Results Log'!$Q$5:$Q$404,"FN") | E5: =COUNTIFS('Results Log'!$G$5:$G$404,"Validation",'Results Log'!$B$5:$B$404,"Expected",'Results Log'!$C$5:$C$404,"Smoking",'Results Log'!$Q$5:$Q$404,"TN") | F5: =COUNTIFS('Results Log'!$G$5:$G$404,"Validation",'Results Log'!$B$5:$B$404,"Expected",'Results Log'!$C$5:$C$404,"Smoking",'Results Log'!$Q$5:$Q$404,"FP") | G5: =COUNTIFS('Results Log'!$G$5:$G$404,"Validation",'Results Log'!$B$5:$B$404,"Unmatched alert",'Results Log'!$C$5:$C$404,"Smoking",'Results Log'!$P$5:$P$404,"False alarm") | H5: =COUNTIFS('Results Log'!$G$5:$G$404,"Validation",'Results Log'!$B$5:$B$404,"Unmatched alert",'Results Log'!$C$5:$C$404,"Smoking",'Results Log'!$P$5:$P$404,"Unscripted – false alarm") | I5: =F5+G5+H5 | J5: =IFERROR((C5+E5)/(C5+D5+E5+I5),"–") | K5: =IFERROR(C5/(C5+I5),"–") | L5: =IFERROR(C5/(C5+D5),"–") | M5: =IFERROR(2*K5*L5/(K5+L5),"–") | N5: =IFERROR(AVERAGEIFS('Results Log'!$N$5:$N$404,'Results Log'!$G$5:$G$404,"Validation",'Results Log'!$Q$5:$Q$404,"TP",'Results Log'!$C$5:$C$404,"Smoking"),"–") | O5: =COUNTIFS('Results Log'!$G$5:$G$404,"Validation",'Results Log'!$B$5:$B$404,"Unmatched alert",'Results Log'!$C$5:$C$404,"Smoking",'Results Log'!$P$5:$P$404,"Duplicate") | P5: =COUNTIFS('Results Log'!$G$5:$G$404,"Validation",'Results Log'!$B$5:$B$404,"Unmatched alert",'Results Log'!$C$5:$C$404,"Smoking",'Results Log'!$P$5:$P$404,"Late (real act)") | Q5: =COUNTIFS('Results Log'!$G$5:$G$404,"Validation",'Results Log'!$B$5:$B$404,"Unmatched alert",'Results Log'!$C$5:$C$404,"Smoking",'Results Log'!$P$5:$P$404,"Unscripted – real violation") | R5: =COUNTIFS('Results Log'!$G$5:$G$404,"Validation",'Results Log'!$C$5:$C$404,"Smoking",'Results Log'!$Q$5:$Q$404,"Needs tag")+COUNTIFS('Results Log'!$G$5:$G$404,"Validation",'Results Log'!$C$5:$C$404,"Smoking",'Results Log'!$Q$5:$Q$404,"Needs start")
A6: Drinking | B6: =C6+D6 | C6: =COUNTIFS('Results Log'!$G$5:$G$404,"Validation",'Results Log'!$B$5:$B$404,"Expected",'Results Log'!$C$5:$C$404,"Drinking",'Results Log'!$Q$5:$Q$404,"TP") | D6: =COUNTIFS('Results Log'!$G$5:$G$404,"Validation",'Results Log'!$B$5:$B$404,"Expected",'Results Log'!$C$5:$C$404,"Drinking",'Results Log'!$Q$5:$Q$404,"FN") | E6: =COUNTIFS('Results Log'!$G$5:$G$404,"Validation",'Results Log'!$B$5:$B$404,"Expected",'Results Log'!$C$5:$C$404,"Drinking",'Results Log'!$Q$5:$Q$404,"TN") | F6: =COUNTIFS('Results Log'!$G$5:$G$404,"Validation",'Results Log'!$B$5:$B$404,"Expected",'Results Log'!$C$5:$C$404,"Drinking",'Results Log'!$Q$5:$Q$404,"FP") | G6: =COUNTIFS('Results Log'!$G$5:$G$404,"Validation",'Results Log'!$B$5:$B$404,"Unmatched alert",'Results Log'!$C$5:$C$404,"Drinking",'Results Log'!$P$5:$P$404,"False alarm") | H6: =COUNTIFS('Results Log'!$G$5:$G$404,"Validation",'Results Log'!$B$5:$B$404,"Unmatched alert",'Results Log'!$C$5:$C$404,"Drinking",'Results Log'!$P$5:$P$404,"Unscripted – false alarm") | I6: =F6+G6+H6 | J6: =IFERROR((C6+E6)/(C6+D6+E6+I6),"–") | K6: =IFERROR(C6/(C6+I6),"–") | L6: =IFERROR(C6/(C6+D6),"–") | M6: =IFERROR(2*K6*L6/(K6+L6),"–") | N6: =IFERROR(AVERAGEIFS('Results Log'!$N$5:$N$404,'Results Log'!$G$5:$G$404,"Validation",'Results Log'!$Q$5:$Q$404,"TP",'Results Log'!$C$5:$C$404,"Drinking"),"–") | O6: =COUNTIFS('Results Log'!$G$5:$G$404,"Validation",'Results Log'!$B$5:$B$404,"Unmatched alert",'Results Log'!$C$5:$C$404,"Drinking",'Results Log'!$P$5:$P$404,"Duplicate") | P6: =COUNTIFS('Results Log'!$G$5:$G$404,"Validation",'Results Log'!$B$5:$B$404,"Unmatched alert",'Results Log'!$C$5:$C$404,"Drinking",'Results Log'!$P$5:$P$404,"Late (real act)") | Q6: =COUNTIFS('Results Log'!$G$5:$G$404,"Validation",'Results Log'!$B$5:$B$404,"Unmatched alert",'Results Log'!$C$5:$C$404,"Drinking",'Results Log'!$P$5:$P$404,"Unscripted – real violation") | R6: =COUNTIFS('Results Log'!$G$5:$G$404,"Validation",'Results Log'!$C$5:$C$404,"Drinking",'Results Log'!$Q$5:$Q$404,"Needs tag")+COUNTIFS('Results Log'!$G$5:$G$404,"Validation",'Results Log'!$C$5:$C$404,"Drinking",'Results Log'!$Q$5:$Q$404,"Needs start")
A7: Parking Obstruction | B7: =C7+D7 | C7: =COUNTIFS('Results Log'!$G$5:$G$404,"Validation",'Results Log'!$B$5:$B$404,"Expected",'Results Log'!$C$5:$C$404,"Parking Obstruction",'Results Log'!$Q$5:$Q$404,"TP") | D7: =COUNTIFS('Results Log'!$G$5:$G$404,"Validation",'Results Log'!$B$5:$B$404,"Expected",'Results Log'!$C$5:$C$404,"Parking Obstruction",'Results Log'!$Q$5:$Q$404,"FN") | E7: =COUNTIFS('Results Log'!$G$5:$G$404,"Validation",'Results Log'!$B$5:$B$404,"Expected",'Results Log'!$C$5:$C$404,"Parking Obstruction",'Results Log'!$Q$5:$Q$404,"TN") | F7: =COUNTIFS('Results Log'!$G$5:$G$404,"Validation",'Results Log'!$B$5:$B$404,"Expected",'Results Log'!$C$5:$C$404,"Parking Obstruction",'Results Log'!$Q$5:$Q$404,"FP") | G7: =COUNTIFS('Results Log'!$G$5:$G$404,"Validation",'Results Log'!$B$5:$B$404,"Unmatched alert",'Results Log'!$C$5:$C$404,"Parking Obstruction",'Results Log'!$P$5:$P$404,"False alarm") | H7: =COUNTIFS('Results Log'!$G$5:$G$404,"Validation",'Results Log'!$B$5:$B$404,"Unmatched alert",'Results Log'!$C$5:$C$404,"Parking Obstruction",'Results Log'!$P$5:$P$404,"Unscripted – false alarm") | I7: =F7+G7+H7 | J7: =IFERROR((C7+E7)/(C7+D7+E7+I7),"–") | K7: =IFERROR(C7/(C7+I7),"–") | L7: =IFERROR(C7/(C7+D7),"–") | M7: =IFERROR(2*K7*L7/(K7+L7),"–") | N7: =IFERROR(AVERAGEIFS('Results Log'!$N$5:$N$404,'Results Log'!$G$5:$G$404,"Validation",'Results Log'!$Q$5:$Q$404,"TP",'Results Log'!$C$5:$C$404,"Parking Obstruction"),"–") | O7: =COUNTIFS('Results Log'!$G$5:$G$404,"Validation",'Results Log'!$B$5:$B$404,"Unmatched alert",'Results Log'!$C$5:$C$404,"Parking Obstruction",'Results Log'!$P$5:$P$404,"Duplicate") | P7: =COUNTIFS('Results Log'!$G$5:$G$404,"Validation",'Results Log'!$B$5:$B$404,"Unmatched alert",'Results Log'!$C$5:$C$404,"Parking Obstruction",'Results Log'!$P$5:$P$404,"Late (real act)") | Q7: =COUNTIFS('Results Log'!$G$5:$G$404,"Validation",'Results Log'!$B$5:$B$404,"Unmatched alert",'Results Log'!$C$5:$C$404,"Parking Obstruction",'Results Log'!$P$5:$P$404,"Unscripted – real violation") | R7: =COUNTIFS('Results Log'!$G$5:$G$404,"Validation",'Results Log'!$C$5:$C$404,"Parking Obstruction",'Results Log'!$Q$5:$Q$404,"Needs tag")+COUNTIFS('Results Log'!$G$5:$G$404,"Validation",'Results Log'!$C$5:$C$404,"Parking Obstruction",'Results Log'!$Q$5:$Q$404,"Needs start")
A8: Holdup | B8: =C8+D8 | C8: =COUNTIFS('Results Log'!$G$5:$G$404,"Validation",'Results Log'!$B$5:$B$404,"Expected",'Results Log'!$C$5:$C$404,"Holdup",'Results Log'!$Q$5:$Q$404,"TP") | D8: =COUNTIFS('Results Log'!$G$5:$G$404,"Validation",'Results Log'!$B$5:$B$404,"Expected",'Results Log'!$C$5:$C$404,"Holdup",'Results Log'!$Q$5:$Q$404,"FN") | E8: =COUNTIFS('Results Log'!$G$5:$G$404,"Validation",'Results Log'!$B$5:$B$404,"Expected",'Results Log'!$C$5:$C$404,"Holdup",'Results Log'!$Q$5:$Q$404,"TN") | F8: =COUNTIFS('Results Log'!$G$5:$G$404,"Validation",'Results Log'!$B$5:$B$404,"Expected",'Results Log'!$C$5:$C$404,"Holdup",'Results Log'!$Q$5:$Q$404,"FP") | G8: =COUNTIFS('Results Log'!$G$5:$G$404,"Validation",'Results Log'!$B$5:$B$404,"Unmatched alert",'Results Log'!$C$5:$C$404,"Holdup",'Results Log'!$P$5:$P$404,"False alarm") | H8: =COUNTIFS('Results Log'!$G$5:$G$404,"Validation",'Results Log'!$B$5:$B$404,"Unmatched alert",'Results Log'!$C$5:$C$404,"Holdup",'Results Log'!$P$5:$P$404,"Unscripted – false alarm") | I8: =F8+G8+H8 | J8: =IFERROR((C8+E8)/(C8+D8+E8+I8),"–") | K8: =IFERROR(C8/(C8+I8),"–") | L8: =IFERROR(C8/(C8+D8),"–") | M8: =IFERROR(2*K8*L8/(K8+L8),"–") | N8: =IFERROR(AVERAGEIFS('Results Log'!$N$5:$N$404,'Results Log'!$G$5:$G$404,"Validation",'Results Log'!$Q$5:$Q$404,"TP",'Results Log'!$C$5:$C$404,"Holdup"),"–") | O8: =COUNTIFS('Results Log'!$G$5:$G$404,"Validation",'Results Log'!$B$5:$B$404,"Unmatched alert",'Results Log'!$C$5:$C$404,"Holdup",'Results Log'!$P$5:$P$404,"Duplicate") | P8: =COUNTIFS('Results Log'!$G$5:$G$404,"Validation",'Results Log'!$B$5:$B$404,"Unmatched alert",'Results Log'!$C$5:$C$404,"Holdup",'Results Log'!$P$5:$P$404,"Late (real act)") | Q8: =COUNTIFS('Results Log'!$G$5:$G$404,"Validation",'Results Log'!$B$5:$B$404,"Unmatched alert",'Results Log'!$C$5:$C$404,"Holdup",'Results Log'!$P$5:$P$404,"Unscripted – real violation") | R8: =COUNTIFS('Results Log'!$G$5:$G$404,"Validation",'Results Log'!$C$5:$C$404,"Holdup",'Results Log'!$Q$5:$Q$404,"Needs tag")+COUNTIFS('Results Log'!$G$5:$G$404,"Validation",'Results Log'!$C$5:$C$404,"Holdup",'Results Log'!$Q$5:$Q$404,"Needs start")
A9: OVERALL | B9: =C9+D9 | C9: =COUNTIFS('Results Log'!$G$5:$G$404,"Validation",'Results Log'!$B$5:$B$404,"Expected",'Results Log'!$Q$5:$Q$404,"TP") | D9: =COUNTIFS('Results Log'!$G$5:$G$404,"Validation",'Results Log'!$B$5:$B$404,"Expected",'Results Log'!$Q$5:$Q$404,"FN") | E9: =COUNTIFS('Results Log'!$G$5:$G$404,"Validation",'Results Log'!$B$5:$B$404,"Expected",'Results Log'!$Q$5:$Q$404,"TN") | F9: =COUNTIFS('Results Log'!$G$5:$G$404,"Validation",'Results Log'!$B$5:$B$404,"Expected",'Results Log'!$Q$5:$Q$404,"FP") | G9: =COUNTIFS('Results Log'!$G$5:$G$404,"Validation",'Results Log'!$B$5:$B$404,"Unmatched alert",'Results Log'!$P$5:$P$404,"False alarm") | H9: =COUNTIFS('Results Log'!$G$5:$G$404,"Validation",'Results Log'!$B$5:$B$404,"Unmatched alert",'Results Log'!$P$5:$P$404,"Unscripted – false alarm") | I9: =F9+G9+H9 | J9: =IFERROR((C9+E9)/(C9+D9+E9+I9),"–") | K9: =IFERROR(C9/(C9+I9),"–") | L9: =IFERROR(C9/(C9+D9),"–") | M9: =IFERROR(2*K9*L9/(K9+L9),"–") | N9: =IFERROR(AVERAGEIFS('Results Log'!$N$5:$N$404,'Results Log'!$G$5:$G$404,"Validation",'Results Log'!$Q$5:$Q$404,"TP"),"–") | O9: =COUNTIFS('Results Log'!$G$5:$G$404,"Validation",'Results Log'!$B$5:$B$404,"Unmatched alert",'Results Log'!$P$5:$P$404,"Duplicate") | P9: =COUNTIFS('Results Log'!$G$5:$G$404,"Validation",'Results Log'!$B$5:$B$404,"Unmatched alert",'Results Log'!$P$5:$P$404,"Late (real act)") | Q9: =COUNTIFS('Results Log'!$G$5:$G$404,"Validation",'Results Log'!$B$5:$B$404,"Unmatched alert",'Results Log'!$P$5:$P$404,"Unscripted – real violation") | R9: =COUNTIFS('Results Log'!$G$5:$G$404,"Validation",'Results Log'!$Q$5:$Q$404,"Needs tag")+COUNTIFS('Results Log'!$G$5:$G$404,"Validation",'Results Log'!$Q$5:$Q$404,"Needs start")

Sheet Breakdown
A1: Breakdown — for Results and Discussion (Main set)
A2: FP here = look-alike/no-violation FP + false alarms (actors or unscripted) in clips with that condition.
A4: 1. By distance
A5: Violation | B5: Distance | C5: Real acts | D5: TP | E5: FN | F5: TN | G5: FP | H5: Accuracy | I5: Precision | J5: Recall
A6: Smoking | B6: Near | C6: =COUNTIFS('Results Log'!$G$5:$G$404,"Main",'Results Log'!$S$5:$S$404,"Near",'Results Log'!$C$5:$C$404,"Smoking",'Results Log'!$B$5:$B$404,"Expected",'Results Log'!$D$5:$D$404,"Violation") | D6: =COUNTIFS('Results Log'!$G$5:$G$404,"Main",'Results Log'!$S$5:$S$404,"Near",'Results Log'!$C$5:$C$404,"Smoking",'Results Log'!$Q$5:$Q$404,"TP") | E6: =COUNTIFS('Results Log'!$G$5:$G$404,"Main",'Results Log'!$S$5:$S$404,"Near",'Results Log'!$C$5:$C$404,"Smoking",'Results Log'!$Q$5:$Q$404,"FN") | F6: =COUNTIFS('Results Log'!$G$5:$G$404,"Main",'Results Log'!$S$5:$S$404,"Near",'Results Log'!$C$5:$C$404,"Smoking",'Results Log'!$Q$5:$Q$404,"TN") | G6: =COUNTIFS('Results Log'!$G$5:$G$404,"Main",'Results Log'!$S$5:$S$404,"Near",'Results Log'!$C$5:$C$404,"Smoking",'Results Log'!$Q$5:$Q$404,"FP") | H6: =IFERROR((D6+F6)/(D6+E6+F6+G6),"–") | I6: =IFERROR(D6/(D6+G6),"–") | J6: =IFERROR(D6/(D6+E6),"–")
